<?xml version="1.0"?>
<robot name="multipleshapes">

  <link name="bl">
    <visual>
      <geometry>
        <box size ="0.04 0.07 0.16"/>
        <origin rpy ="0 0 0" xyz = "0 0 0"/>
      </geometry>
    </visual>
  </link>

  <link name = "base_link">
   <visual>
    <geometry>
     <box size ="0.12 0.07 0.17"/>
    </geometry>
    <origin rpy ="0 0 0" xyz = "0 0 0"/>
     <material name="blue">
        <color rgba="0 0 0.8 1"/>
     </material>
     </visual>
  </link>


  <joint name="joint0" type="continuous">
   <axis xyz = "0 0 1"/>
    <limit effort="1000.0" lower="-3" upper="3" velocity="0.5"/>
   <origin rpy ="0 0 0" xyz = "0 0 0"/>
   <parent link = "base_link"/>
   <child link = "bl"/>
  </joint>

  <link name="link1">
    <visual>
      <geometry>
	<box size="0.07 0.07 0.48"/>
     <!--   <box size="0.07 0.07 0.31"/>    -.2-->
      </geometry>
	<origin rpy="0 0 1.57" xyz="0 0.0 0.22"/>
    </visual>
  </link>

  <joint name="joint1" type="revolute">
    <axis xyz = "1 0 0"/>
    <limit effort="1000.0" lower="-1.727" upper="1.57" velocity="0.25"/>
    <origin rpy ="0.0 0. 0" xyz ="0 0 0.09"/>
    <parent link="bl"/>
    <child link="link1"/>
  </joint>

  <link name = "link2">
   <visual>
     <geometry>
       <box size = "0.03 0.43 0.07"/>
     </geometry>
	<origin rpy= "0 0 0" xyz="0 0.15 0"/>
   </visual>
  </link>

<link name="link_virtual">
<origin rpy= "0 0 0" xyz="0 0.15 0"/>
</link>

  <joint name ="joint2" type="revolute">
   <axis xyz = "1 0 0 "/>
    <limit effort="1000.0" lower="-2.6" upper="2.6" velocity="0.25"/>
   <origin rpy ="0.28 0 0" xyz = "0 0.0 0.43"/>
   <parent link ="link1"/>
   <child link = "link_virtual"/>
  </joint>

<joint name ="joint3" type="revolute">
   <axis xyz = "0 1 0 "/>
    <limit effort="1000.0" lower="-3.61" upper="3.61" velocity="0.25"/>
   <origin rpy ="0 0 0" xyz = "0 0.0 0.0"/>
   <parent link ="link_virtual"/>
   <child link = "link2"/>
  </joint>

  <link name = "link3">
   <visual>
     <geometry>
       <box size = "0.03 0.1 0.07"/>
     </geometry>
	<origin rpy= "0 0 0" xyz="0 0.03 0.0"/>
   </visual>
    <!--collision>
     <geometry>
       <box size = "0.03 0.1 0.07"/>
     </geometry>
	<origin rpy= "0 0 0" xyz="0 0.03 0.0"/>
    </collision-->
  </link>

  <joint name ="joint4" type="revolute">
   <axis xyz = "1 0 0 "/>
    <limit effort="1000.0" lower="-1.64" upper="1.64" velocity="0.25"/>
   <origin rpy ="0 0 0" xyz = "0 0.38 0.0"/>
   <parent link ="link2"/>
   <child link = "link3"/>
  </joint>

  <link name = "link4">
   <visual>
     <geometry>
       <box size = "0.03 0.1 0.03"/>
     </geometry>
	<origin rpy= "0 0 0" xyz="0 0.03 0.0"/>
   </visual>
    <!--collision>
     <geometry>
       <box size = "0.03 0.1 0.03"/>
     </geometry>
	<origin rpy= "0 0 0" xyz="0 0.03 0.0"/>
    </collision-->
  </link>

  <joint name ="joint5" type="revolute">
   <axis xyz = "0 1 0 "/>
    <limit effort="1000.0" lower="-2.44" upper="2.44" velocity="0.25"/>
   <origin rpy ="0 0 0" xyz = "0 0.1 0.0"/>
   <parent link ="link3"/>
   <child link = "link4"/>
  </joint>



  <!--link name = "gripper_link">
   <visual>
     <geometry>
       <box size = "0.03 0.06 0.03"/>
     </geometry>
	<origin rpy= "0 0 0" xyz="0 0.05 0.0"/>
   </visual>
  </link>

  <joint name ="gripper" type="revolute">
   <axis xyz = "0 0 1 "/>
    <limit effort="1000.0" lower="-2.44" upper="2.44" velocity="0.25"/>
   <origin rpy ="0 0 0" xyz = "0 0.05 0.0"/>
   <parent link ="link4"/>
   <child link = "gripper_link"/>
  </joint-->







<!--link name="kinect_depth_HASHMARK_0">
<origin rpy= "0 0 0" xyz="0 0 0"/>
</link>

<joint name="kinect_joint#0" type="fixed">
    <parent link="link0"/>
    <child link="kinect_depth_HASHMARK_0"/>
    <origin rpy="1.57 0 3.14" xyz="-0.0143 0.0302 0.7448"/>
    <axis xyz="0 0 0" />
</joint-->


<link name="camera_link">
<origin rpy= "0 0 0" xyz="0 0 0"/>
</link>
<joint name="kinect_joint1" type="fixed">
    <parent link="base_link"/>
    <child link="camera_link"/>
    <origin rpy="1.57079632679 0 3.14159265359" xyz="0.10 -0.1 0.48"/>
    <axis xyz="0 0 0" />
</joint>


    <!--origin rpy="0 0 0" xyz="-0.035 0.3 0.02"/-->





<!--link name="kinect_depth_HASHMARK_0">
<origin rpy= "0 0 0" xyz="0 0.1 0"/>

</link>





<joint name="kinect_joint#0" type="fixed">
    <parent link="link4"/>
    <child link="kinect_depth_HASHMARK_0"/>
    <origin rpy="1.75 0 3.14" xyz="0.0 0.01 0"/>
    <axis xyz="0 0 0" />
    <limit effort="1000.0" lower="-3" upper="3" velocity="0.5"/>1.57 0 3.14159
</joint>-->

<Manipulator name="arm_kin_chain">
   <!-- tip -->
   <effector>link4</effector>
   <!-- origin -->
   <base>base_link</base>

   <!-- no additional info is required since it is a leg -->
</Manipulator>

</robot>
