<?xml version="1.0"?>
<robot name="Base_arm">

  <!-- Lea dimentions: xbase=0.55 ybase= 0.428 zbase=~0.932 -->
  <!-- Lea positions from center base: x=0 y=0 z=rweel+zbase/2=0.666  -->

  <!-- Lea wheel dimentions: rwheel=0.20 twheel=~0.04 rcwheel=0.2 twheel=~0.03 -->

  <!-- Lea wheel positions from center base: xwheel=0.275 ywheel=0.214 zwheel=rwheel=0.20  -->
  <!-- Lea custerwheel positions from center base: xcwheel=0.203 ycwheel=-0.214 zcwheel=rwheel=0.20  -->
  <link name="base_link">
    <visual>
      <origin xyz="0 0 0.666" rpy="0 0 0"/>
      <geometry>
        <box size="0.55 0.428 0.666"/>
      </geometry>
    </visual>
  </link>

  <!-- Back wheels-->
  <link name="right_wheel">
    <visual>
      <origin xyz="0 0 0" rpy="0 0 0"/>
      <geometry>
        <cylinder radius="0.1" length="0.04"/>
      </geometry>
    </visual>
  </link>

  <joint name="right_wheel_joint" type="continuous">
    <axis xyz="0 0 1" rpy="0 0 0"/>
    <parent link="base_link"/>
    <child link="right_wheel"/>
    <origin xyz="0.275 .214 0.2" rpy="0 1.57 0"/>
  </joint>

  <link name="left_wheel">
    <visual>
      <origin xyz="0 0 0" rpy="0 0 0"/>
      <geometry>
        <cylinder radius="0.1" length="0.04"/>
      </geometry>
    </visual>
  </link>

  <joint name="left_wheel_joint" type="continuous">
    <axis xyz="0 0 1" rpy="0 0 0"/>
    <parent link="base_link"/>
    <child link="left_wheel"/>
    <origin xyz="-0.275 .214 0.2" rpy="0 1.57 0"/>
  </joint>

  <!-- custer wheels right-->
  <link name="right_cwheel">
    <visual>
      <origin xyz="0 0 0" rpy="0 0 0"/>
      <geometry>
        <cylinder radius="0.1" length="0.03"/>
      </geometry>
    </visual>
  </link>

  <link name="right_joint">
    <visual>
      <origin xyz="0 0.01 0.12" rpy="0 0 0"/>
      <geometry>
        <box size="0.01 0.01 0.01"/>
      </geometry>
    </visual>
  </link>

  <joint name="right_cwheel_joint1" type="continuous">
    <axis xyz="0 0 1" rpy="0 0 0"/>
    <parent link="base_link"/>
    <child link="right_joint"/>
    <origin xyz="0.203 -.214 0.2" rpy="0 0 0"/>
  </joint>

  <joint name="right_cwheel_joint2" type="continuous">
    <axis xyz="0 0 1" rpy="0 0 0"/>
    <parent link="right_joint"/>
    <child link="right_cwheel"/>
    <origin xyz="0 -0.05 0" rpy="0 1.57 0"/>
  </joint>

  <!-- custer wheels left-->
  <link name="left_cwheel">
    <visual>
      <origin xyz="0 0 0" rpy="0 0 0"/>
      <geometry>
        <cylinder radius="0.1" length="0.03"/>
      </geometry>
    </visual>
  </link>

  <link name="left_joint">
    <visual>
      <origin xyz="0 0 0.12" rpy="0 0 0"/>
      <geometry>
        <box size="0.01 0.01 0.01"/>
      </geometry>
    </visual>
  </link>

  <joint name="left_cwheel_joint1" type="continuous">
    <axis xyz="0 0 1" rpy="0 0 0"/>
    <parent link="base_link"/>
    <child link="left_joint"/>
    <origin xyz="-0.203 -.214 0.2" rpy="0 0 0"/>
  </joint>

  <joint name="left_cwheel_joint2" type="continuous">
    <axis xyz="0 0 1" rpy="0 0 0"/>
    <parent link="left_joint"/>
    <child link="left_cwheel"/>
    <origin xyz="0 -0.05 0" rpy="0 1.57 0"/>
  </joint>



  <link name = "link0">
   <visual>
    <geometry>
     <box size ="0.12 0.07 0.17"/>
    </geometry>
    <origin rpy ="0 0 0" xyz = "0 0 0"/>
     <material name="blue">
        <color rgba="0 0 0.8 1"/>
     </material>
     </visual>
  </link>


  <joint name="joint_arm_base" type="fixed">
   <axis xyz = "0 0 1"/>
   <origin rpy ="0 0 -3.14" xyz = "0 -0.214 1.066"/>
   <parent link = "base_link"/>
   <child link = "link0"/>
  </joint>

  <link name="bl">
    <visual>
      <geometry>
        <box size ="0.04 0.07 0.16"/>
        <origin rpy ="0 0 0" xyz = "0 0 0"/>
      </geometry>
    </visual>
  </link>



  <joint name="joint0" type="continuous">
   <axis xyz = "0 0 1"/>
    <limit effort="1000.0" lower="-3" upper="3" velocity="0.5"/>
   <origin rpy ="0 0 0" xyz = "0 0 0"/>
   <parent link = "link0"/>
   <child link = "bl"/>
  </joint>

  <link name="link1">
    <visual>
      <geometry>
	<box size="0.07 0.07 0.48"/>
      </geometry>
	<origin rpy="0 0 1.57" xyz="0 0.0 0.22"/>
    </visual>
  </link>

  <joint name="joint1" type="revolute">
    <axis xyz = "1 0 0"/>
    <limit effort="1000.0" lower="-1.727" upper="1.57" velocity="0.25"/>
    <origin rpy ="0.0 0. 0" xyz ="0 0 0.09"/>
    <parent link="bl"/>
    <child link="link1"/>
  </joint>

  <link name = "link2">
   <visual>
     <geometry>
       <box size = "0.03 0.43 0.07"/>
     </geometry>
	<origin rpy= "0 0 0" xyz="0 0.15 0"/>
   </visual>
  </link>

<link name="link_virtual">
<origin rpy= "0 0 0" xyz="0 0.15 0"/>
</link>

  <joint name ="joint2" type="revolute">
   <axis xyz = "1 0 0 "/>
    <limit effort="1000.0" lower="-2.6" upper="2.6" velocity="0.25"/>
   <origin rpy ="0.28 0 0" xyz = "0 0.0 0.43"/>
   <parent link ="link1"/>
   <child link = "link_virtual"/>
  </joint>

<joint name ="joint3" type="revolute">
   <axis xyz = "0 1 0 "/>
    <limit effort="1000.0" lower="-3.61" upper="3.61" velocity="0.25"/>
   <origin rpy ="0 0 0" xyz = "0 0.0 0.0"/>
   <parent link ="link_virtual"/>
   <child link = "link2"/>
  </joint>

  <link name = "link3">
   <visual>
     <geometry>
       <box size = "0.03 0.1 0.07"/>
     </geometry>
	<origin rpy= "0 0 0" xyz="0 0.03 0.0"/>
   </visual>
  </link>

  <joint name ="joint4" type="revolute">
   <axis xyz = "1 0 0 "/>
    <limit effort="1000.0" lower="-1.64" upper="1.64" velocity="0.25"/>
   <origin rpy ="0 0 0" xyz = "0 0.38 0.0"/>
   <parent link ="link2"/>
   <child link = "link3"/>
  </joint>

  <link name = "link4">
   <visual>
     <geometry>
       <box size = "0.03 0.1 0.03"/>
     </geometry>
	<origin rpy= "0 0 0" xyz="0 0.03 0.0"/>
   </visual>
  </link>

  <joint name ="joint5" type="revolute">
   <axis xyz = "0 1 0 "/>
    <limit effort="1000.0" lower="-2.44" upper="2.44" velocity="0.25"/>
   <origin rpy ="0 0 0" xyz = "0 0.1 0.0"/>
   <parent link ="link3"/>
   <child link = "link4"/>
  </joint>


<link name="camera_link">
<origin rpy= "0 0 0" xyz="0 0 0"/>
</link>
<joint name="kinect_joint1" type="fixed">
    <parent link="link0"/>
    <child link="camera_link"/>
    <origin rpy="1.57079632679 0 3.14159265359" xyz="0.10 -0.1 0.48"/>
    <axis xyz="0 0 0" />
</joint>



</robot>
