<?xml version="1.0"?>
<robot name="new_arm_base_link">


<!-- ARM -->
  <link name="base_link">
    <visual>
      <geometry>
        <box size="0.12 0.07 0.17"/>
      </geometry>
      <origin rpy="0 0 0" xyz="0 0 0"/>
      <material name="blue">
        <color rgba="0 0 0.8 1"/>
      </material>
    </visual>
  </link>

  <link name="bl">
    <visual>
      <origin rpy="0 0 0" xyz="0 0 0"/>
      <geometry>
        <box size="0.04 0.07 0.16"/>
      </geometry>
    </visual>
  </link>

  <joint name="joint0" type="continuous">
    <axis xyz="0 0 1"/>
    <limit effort="1000.0" lower="-3" upper="3" velocity="0.5"/>
    <origin rpy="0 0 0" xyz="0 0 0"/>
    <parent link="base_link"/>
    <child link="bl"/>
  </joint>

  <link name="link1">
    <visual>
      <geometry>
        <box size="0.07 0.07 0.48"/>
      </geometry>
      <origin rpy="0 0 1.57" xyz="0 0.0 0.22"/>
      <material name="green">
        <color rgba="0 0.8 0 1"/>
      </material>
    </visual>
  </link>

  <joint name="joint1" type="revolute">
    <axis xyz="1 0 0"/>
    <limit effort="1000.0" lower="-1.727" upper="1.57" velocity="0.25"/>
    <origin rpy="0.0 0. 0" xyz="0 0 0.09"/>
    <parent link="bl"/>
    <child link="link1"/>
  </joint>

  <link name="link2">
    <visual>
      <geometry>
        <box size="0.03 0.43 0.07"/>
      </geometry>
      <origin rpy="0 0 0" xyz="0 0.15 0"/>
      <material name="magenta">
        <color rgba="0.8 0 0.8 1"/>
      </material>
    </visual>
  </link>

  <link name="link_virtual">
    <visual>
      <geometry>
        <box size="0.03 0.01 0.07"/>
      </geometry>
      <origin rpy="0 0 1.57" xyz="0 0.0 0"/>
      <material name="magenta">
        <color rgba="0.8 0 0.8 1"/>
      </material>
    </visual>
  </link>

  <!-- <link name="link_virtual">
    <origin rpy="0 0 0" xyz="0 0.15 0"/>
  </link> -->

    <!-- 0.28 was the original value, subtracted pi/2 -->
  <joint name="joint2" type="revolute">
    <axis xyz="1 0 0 "/>
    <limit effort="1000.0" lower="-2.6" upper="2.6" velocity="0.25"/>
    <origin rpy="-1.29 0 0" xyz="0 0.0 0.43"/>

    <parent link="link1"/>
    <child link="link_virtual"/>
  </joint>

  <joint name="joint3" type="revolute">
    <axis xyz="0 1 0 "/>
    <limit effort="1000.0" lower="-3.61" upper="3.61" velocity="0.25"/>
    <origin rpy="0 0 0" xyz="0 0.0 0.0"/>
    <parent link="link_virtual"/>
    <child link="link2"/>
  </joint>

  <link name="link3">
    <visual>
      <geometry>
        <box size="0.03 0.1 0.07"/>
      </geometry>
      <origin rpy="0 0 0" xyz="0 0.03 0.0"/>
      <material name="yellow">
        <color rgba="0.8 0.8 0 1"/>
      </material>
    </visual>
  </link>

  <joint name="joint4" type="revolute">
    <axis xyz="1 0 0 "/>
    <limit effort="1000.0" lower="-1.64" upper="1.64" velocity="0.25"/>
    <origin rpy="0 0 0" xyz="0 0.38 0.0"/>
    <parent link="link2"/>
    <child link="link3"/>
  </joint>

  <link name="link4">
    <visual>
      <geometry>
        <box size="0.03 0.1 0.03"/>
      </geometry>
      <origin rpy="0 0 0" xyz="0 0.03 0.0"/>
    </visual>
  </link>

  <joint name="joint5" type="revolute">
    <axis xyz="0 1 0 "/>
    <limit effort="1000.0" lower="-2.44" upper="2.44" velocity="0.25"/>
    <origin rpy="0 0 0" xyz="0 0.1 0.0"/>
    <parent link="link3"/>
    <child link="link4"/>
  </joint>


</robot>
